2024-04-27 12:04:06,234 INFO    MainThread:1119142 [wandb_setup.py:_flush():76] Current SDK version is 0.16.3
2024-04-27 12:04:06,234 INFO    MainThread:1119142 [wandb_setup.py:_flush():76] Configure stats pid to 1119142
2024-04-27 12:04:06,235 INFO    MainThread:1119142 [wandb_setup.py:_flush():76] Loading settings from /home/x_souba/.config/wandb/settings
2024-04-27 12:04:06,235 INFO    MainThread:1119142 [wandb_setup.py:_flush():76] Loading settings from /proj/sourasb-220503/Fed-DIPA2/wandb/settings
2024-04-27 12:04:06,235 INFO    MainThread:1119142 [wandb_setup.py:_flush():76] Loading settings from environment variables: {}
2024-04-27 12:04:06,235 INFO    MainThread:1119142 [wandb_setup.py:_flush():76] Applying setup settings: {'_disable_service': False}
2024-04-27 12:04:06,235 INFO    MainThread:1119142 [wandb_setup.py:_flush():76] Inferring run settings from compute environment: {'program_relpath': 'main.py', 'program_abspath': '/proj/sourasb-220503/Fed-DIPA2/main.py', 'program': '/proj/sourasb-220503/Fed-DIPA2/main.py'}
2024-04-27 12:04:06,235 INFO    MainThread:1119142 [wandb_init.py:_log_setup():526] Logging user logs to /proj/sourasb-220503/Fed-DIPA2/wandb/run-20240427_120406-3gppb3jk/logs/debug.log
2024-04-27 12:04:06,236 INFO    MainThread:1119142 [wandb_init.py:_log_setup():527] Logging internal logs to /proj/sourasb-220503/Fed-DIPA2/wandb/run-20240427_120406-3gppb3jk/logs/debug-internal.log
2024-04-27 12:04:06,236 INFO    MainThread:1119142 [wandb_init.py:init():566] calling init triggers
2024-04-27 12:04:06,236 INFO    MainThread:1119142 [wandb_init.py:init():573] wandb.init called with sweep_config: {}
config: {}
2024-04-27 12:04:06,236 INFO    MainThread:1119142 [wandb_init.py:init():616] starting backend
2024-04-27 12:04:06,236 INFO    MainThread:1119142 [wandb_init.py:init():620] setting up manager
2024-04-27 12:04:06,237 INFO    MainThread:1119142 [backend.py:_multiprocessing_setup():105] multiprocessing start_methods=fork,spawn,forkserver, using: spawn
2024-04-27 12:04:06,239 INFO    MainThread:1119142 [wandb_init.py:init():628] backend started and connected
2024-04-27 12:04:06,241 INFO    MainThread:1119142 [wandb_init.py:init():720] updated telemetry
2024-04-27 12:04:06,255 INFO    MainThread:1119142 [wandb_init.py:init():753] communicating run to backend with 90.0 second timeout
2024-04-27 12:05:04,507 INFO    Thread-1 (wrapped_target):1119142 [retry.py:__call__():172] Retry attempt failed:
Traceback (most recent call last):
  File "/home/x_souba/anaconda3/envs/personalized_fl/lib/python3.11/site-packages/urllib3/connectionpool.py", line 536, in _make_request
    response = conn.getresponse()
               ^^^^^^^^^^^^^^^^^^
  File "/home/x_souba/anaconda3/envs/personalized_fl/lib/python3.11/site-packages/urllib3/connection.py", line 454, in getresponse
    httplib_response = super().getresponse()
                       ^^^^^^^^^^^^^^^^^^^^^
  File "/home/x_souba/anaconda3/envs/personalized_fl/lib/python3.11/http/client.py", line 1375, in getresponse
    response.begin()
  File "/home/x_souba/anaconda3/envs/personalized_fl/lib/python3.11/http/client.py", line 318, in begin
    version, status, reason = self._read_status()
                              ^^^^^^^^^^^^^^^^^^^
  File "/home/x_souba/anaconda3/envs/personalized_fl/lib/python3.11/http/client.py", line 279, in _read_status
    line = str(self.fp.readline(_MAXLINE + 1), "iso-8859-1")
               ^^^^^^^^^^^^^^^^^^^^^^^^^^^^^^
  File "/home/x_souba/anaconda3/envs/personalized_fl/lib/python3.11/socket.py", line 706, in readinto
    return self._sock.recv_into(b)
           ^^^^^^^^^^^^^^^^^^^^^^^
  File "/home/x_souba/anaconda3/envs/personalized_fl/lib/python3.11/ssl.py", line 1278, in recv_into
    return self.read(nbytes, buffer)
           ^^^^^^^^^^^^^^^^^^^^^^^^^
  File "/home/x_souba/anaconda3/envs/personalized_fl/lib/python3.11/ssl.py", line 1134, in read
    return self._sslobj.read(len, buffer)
           ^^^^^^^^^^^^^^^^^^^^^^^^^^^^^^
TimeoutError: The read operation timed out

The above exception was the direct cause of the following exception:

Traceback (most recent call last):
  File "/home/x_souba/anaconda3/envs/personalized_fl/lib/python3.11/site-packages/requests/adapters.py", line 486, in send
    resp = conn.urlopen(
           ^^^^^^^^^^^^^
  File "/home/x_souba/anaconda3/envs/personalized_fl/lib/python3.11/site-packages/urllib3/connectionpool.py", line 844, in urlopen
    retries = retries.increment(
              ^^^^^^^^^^^^^^^^^^
  File "/home/x_souba/anaconda3/envs/personalized_fl/lib/python3.11/site-packages/urllib3/util/retry.py", line 470, in increment
    raise reraise(type(error), error, _stacktrace)
          ^^^^^^^^^^^^^^^^^^^^^^^^^^^^^^^^^^^^^^^^
  File "/home/x_souba/anaconda3/envs/personalized_fl/lib/python3.11/site-packages/urllib3/util/util.py", line 39, in reraise
    raise value
  File "/home/x_souba/anaconda3/envs/personalized_fl/lib/python3.11/site-packages/urllib3/connectionpool.py", line 790, in urlopen
    response = self._make_request(
               ^^^^^^^^^^^^^^^^^^^
  File "/home/x_souba/anaconda3/envs/personalized_fl/lib/python3.11/site-packages/urllib3/connectionpool.py", line 538, in _make_request
    self._raise_timeout(err=e, url=url, timeout_value=read_timeout)
  File "/home/x_souba/anaconda3/envs/personalized_fl/lib/python3.11/site-packages/urllib3/connectionpool.py", line 370, in _raise_timeout
    raise ReadTimeoutError(
urllib3.exceptions.ReadTimeoutError: HTTPSConnectionPool(host='api.wandb.ai', port=443): Read timed out. (read timeout=20)

During handling of the above exception, another exception occurred:

Traceback (most recent call last):
  File "/home/x_souba/anaconda3/envs/personalized_fl/lib/python3.11/site-packages/wandb/sdk/lib/retry.py", line 131, in __call__
    result = self._call_fn(*args, **kwargs)
             ^^^^^^^^^^^^^^^^^^^^^^^^^^^^^^
  File "/home/x_souba/anaconda3/envs/personalized_fl/lib/python3.11/site-packages/wandb/sdk/internal/internal_api.py", line 369, in execute
    return self.client.execute(*args, **kwargs)  # type: ignore
           ^^^^^^^^^^^^^^^^^^^^^^^^^^^^^^^^^^^^
  File "/home/x_souba/anaconda3/envs/personalized_fl/lib/python3.11/site-packages/wandb/vendor/gql-0.2.0/wandb_gql/client.py", line 52, in execute
    result = self._get_result(document, *args, **kwargs)
             ^^^^^^^^^^^^^^^^^^^^^^^^^^^^^^^^^^^^^^^^^^^
  File "/home/x_souba/anaconda3/envs/personalized_fl/lib/python3.11/site-packages/wandb/vendor/gql-0.2.0/wandb_gql/client.py", line 60, in _get_result
    return self.transport.execute(document, *args, **kwargs)
           ^^^^^^^^^^^^^^^^^^^^^^^^^^^^^^^^^^^^^^^^^^^^^^^^^
  File "/home/x_souba/anaconda3/envs/personalized_fl/lib/python3.11/site-packages/wandb/sdk/lib/gql_request.py", line 58, in execute
    request = self.session.post(self.url, **post_args)
              ^^^^^^^^^^^^^^^^^^^^^^^^^^^^^^^^^^^^^^^^
  File "/home/x_souba/anaconda3/envs/personalized_fl/lib/python3.11/site-packages/requests/sessions.py", line 637, in post
    return self.request("POST", url, data=data, json=json, **kwargs)
           ^^^^^^^^^^^^^^^^^^^^^^^^^^^^^^^^^^^^^^^^^^^^^^^^^^^^^^^^^
  File "/home/x_souba/anaconda3/envs/personalized_fl/lib/python3.11/site-packages/requests/sessions.py", line 589, in request
    resp = self.send(prep, **send_kwargs)
           ^^^^^^^^^^^^^^^^^^^^^^^^^^^^^^
  File "/home/x_souba/anaconda3/envs/personalized_fl/lib/python3.11/site-packages/requests/sessions.py", line 703, in send
    r = adapter.send(request, **kwargs)
        ^^^^^^^^^^^^^^^^^^^^^^^^^^^^^^^
  File "/home/x_souba/anaconda3/envs/personalized_fl/lib/python3.11/site-packages/requests/adapters.py", line 532, in send
    raise ReadTimeout(e, request=request)
requests.exceptions.ReadTimeout: HTTPSConnectionPool(host='api.wandb.ai', port=443): Read timed out. (read timeout=20)
2024-04-27 12:05:27,792 INFO    MainThread:1119142 [wandb_run.py:_on_init():2262] communicating current version
2024-04-27 12:05:27,830 INFO    MainThread:1119142 [wandb_run.py:_on_init():2271] got version response upgrade_message: "wandb version 0.16.6 is available!  To upgrade, please run:\n $ pip install wandb --upgrade"

2024-04-27 12:05:27,831 INFO    MainThread:1119142 [wandb_init.py:init():804] starting run threads in backend
2024-04-27 12:05:35,716 INFO    MainThread:1119142 [wandb_run.py:_console_start():2241] atexit reg
2024-04-27 12:05:35,716 INFO    MainThread:1119142 [wandb_run.py:_redirect():2096] redirect: wrap_raw
2024-04-27 12:05:35,716 INFO    MainThread:1119142 [wandb_run.py:_redirect():2161] Wrapping output streams.
2024-04-27 12:05:35,717 INFO    MainThread:1119142 [wandb_run.py:_redirect():2186] Redirects installed.
2024-04-27 12:05:35,717 INFO    MainThread:1119142 [wandb_init.py:init():847] run started, returning control to user process
2024-04-27 12:06:46,240 INFO    MainThread:1119142 [wandb_run.py:_finish():1970] finishing run sourasb/DIPA2/3gppb3jk
2024-04-27 12:06:46,240 INFO    MainThread:1119142 [wandb_run.py:_atexit_cleanup():2210] got exitcode: 0
2024-04-27 12:06:46,241 INFO    MainThread:1119142 [wandb_run.py:_restore():2193] restore
2024-04-27 12:06:46,242 INFO    MainThread:1119142 [wandb_run.py:_restore():2199] restore done
2024-04-27 12:06:53,472 INFO    MainThread:1119142 [wandb_run.py:_footer_history_summary_info():3866] rendering history
2024-04-27 12:06:53,473 INFO    MainThread:1119142 [wandb_run.py:_footer_history_summary_info():3898] rendering summary
2024-04-27 12:06:53,480 INFO    MainThread:1119142 [wandb_run.py:_footer_sync_info():3825] logging synced files
